Workbook

Sheet START HERE
B2: Small Business Content & Planning Vault
B4: 1. Settings | C4: Type your business name, topic, product and year once. Idea Bank and Calendar update.
B5: 2. Idea Bank | C5: 90 ready-to-post prompts across 6 content pillars. Filter by pillar or platform.
B6: 3. Content Calendar | C6: A full year, one tab per quarter-style layout: date, platform, pillar, status, caption.
B7: 4. Weekly Planner | C7: Top 3 priorities, daily blocks, habits, wins. Duplicate the tab each week.
B8: 5. Budget Tracker | C8: Monthly income and expenses with automatic totals and profit.
B9: 6. Post Tracker | C9: Log results (reach, likes, clicks, sales) and see engagement rate and best pillar.
B11: Google Sheets | C11: File > Import > Upload > 'Replace spreadsheet'. Everything works, including dropdowns and formulas.
B12: Notion | C12: Import the CSVs from the Notion_CSVs folder: Add > Import > CSV.
B13: Tip | C13: Edit only the cream-coloured input cells. Gray/green cells contain formulas.

Sheet Settings
B2: Settings (edit the cream cells)
B4: Business name | C4: My Business
B5: Main topic | C5: my niche
B6: Goal customers want | C6: get started
B7: Product / offer | C7: my signature offer
B8: Ideal customer | C8: customer
B9: Year | C9: 2027

Sheet Idea Bank
A1: # | B1: Pillar | C1: Idea template | D1: Your version (auto-filled) | E1: Best platform | F1: Used?
A2: 1 | B2: Educate | C2: 3 mistakes beginners make with {topic} | D2: =SUBSTITUTE(SUBSTITUTE(SUBSTITUTE(SUBSTITUTE(SUBSTITUTE(C2,"{topic}",Settings!$C$5),"{goal}",Settings!$C$6),"{product}",Settings!$C$7),"{customer}",Settings!$C$8),"{brand}",Settings!$C$4) | E2: TikTok | F2: No
A3: 2 | B3: Educate | C3: How to {goal} in 5 steps | D3: =SUBSTITUTE(SUBSTITUTE(SUBSTITUTE(SUBSTITUTE(SUBSTITUTE(C3,"{topic}",Settings!$C$5),"{goal}",Settings!$C$6),"{product}",Settings!$C$7),"{customer}",Settings!$C$8),"{brand}",Settings!$C$4) | E3: Facebook | F3: No
A4: 3 | B4: Educate | C4: Myth vs fact: {topic} | D4: =SUBSTITUTE(SUBSTITUTE(SUBSTITUTE(SUBSTITUTE(SUBSTITUTE(C4,"{topic}",Settings!$C$5),"{goal}",Settings!$C$6),"{product}",Settings!$C$7),"{customer}",Settings!$C$8),"{brand}",Settings!$C$4) | E4: LinkedIn | F4: No
A5: 4 | B5: Educate | C5: A simple checklist for {goal} | D5: =SUBSTITUTE(SUBSTITUTE(SUBSTITUTE(SUBSTITUTE(SUBSTITUTE(C5,"{topic}",Settings!$C$5),"{goal}",Settings!$C$6),"{product}",Settings!$C$7),"{customer}",Settings!$C$8),"{brand}",Settings!$C$4) | E5: Pinterest | F5: No
A6: 5 | B6: Educate | C6: What I wish I knew before starting {topic} | D6: =SUBSTITUTE(SUBSTITUTE(SUBSTITUTE(SUBSTITUTE(SUBSTITUTE(C6,"{topic}",Settings!$C$5),"{goal}",Settings!$C$6),"{product}",Settings!$C$7),"{customer}",Settings!$C$8),"{brand}",Settings!$C$4) | E6: Email | F6: No
A7: 6 | B7: Educate | C7: Quick tip: the fastest way to {goal} | D7: =SUBSTITUTE(SUBSTITUTE(SUBSTITUTE(SUBSTITUTE(SUBSTITUTE(C7,"{topic}",Settings!$C$5),"{goal}",Settings!$C$6),"{product}",Settings!$C$7),"{customer}",Settings!$C$8),"{brand}",Settings!$C$4) | E7: Instagram | F7: No
A8: 7 | B8: Educate | C8: Beginner glossary: 5 {topic} terms explained | D8: =SUBSTITUTE(SUBSTITUTE(SUBSTITUTE(SUBSTITUTE(SUBSTITUTE(C8,"{topic}",Settings!$C$5),"{goal}",Settings!$C$6),"{product}",Settings!$C$7),"{customer}",Settings!$C$8),"{brand}",Settings!$C$4) | E8: TikTok | F8: No
A9: 8 | B9: Educate | C9: Tool stack I use for {topic} | D9: =SUBSTITUTE(SUBSTITUTE(SUBSTITUTE(SUBSTITUTE(SUBSTITUTE(C9,"{topic}",Settings!$C$5),"{goal}",Settings!$C$6),"{product}",Settings!$C$7),"{customer}",Settings!$C$8),"{brand}",Settings!$C$4) | E9: Facebook | F9: No
A10: 9 | B10: Educate | C10: Before/after: {goal} | D10: =SUBSTITUTE(SUBSTITUTE(SUBSTITUTE(SUBSTITUTE(SUBSTITUTE(C10,"{topic}",Settings!$C$5),"{goal}",Settings!$C$6),"{product}",Settings!$C$7),"{customer}",Settings!$C$8),"{brand}",Settings!$C$4) | E10: LinkedIn | F10: No
A11: 10 | B11: Educate | C11: FAQ: your top question about {topic} | D11: =SUBSTITUTE(SUBSTITUTE(SUBSTITUTE(SUBSTITUTE(SUBSTITUTE(C11,"{topic}",Settings!$C$5),"{goal}",Settings!$C$6),"{product}",Settings!$C$7),"{customer}",Settings!$C$8),"{brand}",Settings!$C$4) | E11: Pinterest | F11: No
A12: 11 | B12: Educate | C12: Common {topic} objections, answered | D12: =SUBSTITUTE(SUBSTITUTE(SUBSTITUTE(SUBSTITUTE(SUBSTITUTE(C12,"{topic}",Settings!$C$5),"{goal}",Settings!$C$6),"{product}",Settings!$C$7),"{customer}",Settings!$C$8),"{brand}",Settings!$C$4) | E12: Email | F12: No
A13: 12 | B13: Educate | C13: The 80/20 of {topic} | D13: =SUBSTITUTE(SUBSTITUTE(SUBSTITUTE(SUBSTITUTE(SUBSTITUTE(C13,"{topic}",Settings!$C$5),"{goal}",Settings!$C$6),"{product}",Settings!$C$7),"{customer}",Settings!$C$8),"{brand}",Settings!$C$4) | E13: Instagram | F13: No
... A91: 90 | B91: Engage / community | C91: Giveaway / challenge | D91: =SUBSTITUTE(SUBSTITUTE(SUBSTITUTE(SUBSTITUTE(SUBSTITUTE(C91,"{topic}",Settings!$C$5),"{goal}",Settings!$C$6),"{product}",Settings!$C$7),"{customer}",Settings!$C$8),"{brand}",Settings!$C$4) | E91: Instagram | F91: No

Sheet Content Calendar
A1: Date | B1: Day | C1: Month | D1: Platform | E1: Pillar | F1: Idea / topic | G1: Caption | H1: Status | I1: Link
A2: =DATE(Settings!$C$9,1,1)+MOD(7-WEEKDAY(DATE(Settings!$C$9,1,1),3),7)+0 | B2: =TEXT(A2,"dddd") | C2: =TEXT(A2,"mmmm") | D2: Instagram | E2: Educate | H2: Idea
A3: =DATE(Settings!$C$9,1,1)+MOD(7-WEEKDAY(DATE(Settings!$C$9,1,1),3),7)+2 | B3: =TEXT(A3,"dddd") | C3: =TEXT(A3,"mmmm") | D3: Facebook | E3: Behind the scenes | H3: Idea
A4: =DATE(Settings!$C$9,1,1)+MOD(7-WEEKDAY(DATE(Settings!$C$9,1,1),3),7)+4 | B4: =TEXT(A4,"dddd") | C4: =TEXT(A4,"mmmm") | D4: Instagram | E4: Social proof | H4: Idea
A5: =DATE(Settings!$C$9,1,1)+MOD(7-WEEKDAY(DATE(Settings!$C$9,1,1),3),7)+7 | B5: =TEXT(A5,"dddd") | C5: =TEXT(A5,"mmmm") | D5: Instagram | E5: Offer / promo | H5: Idea
A6: =DATE(Settings!$C$9,1,1)+MOD(7-WEEKDAY(DATE(Settings!$C$9,1,1),3),7)+9 | B6: =TEXT(A6,"dddd") | C6: =TEXT(A6,"mmmm") | D6: Facebook | E6: Personal story | H6: Idea
A7: =DATE(Settings!$C$9,1,1)+MOD(7-WEEKDAY(DATE(Settings!$C$9,1,1),3),7)+11 | B7: =TEXT(A7,"dddd") | C7: =TEXT(A7,"mmmm") | D7: Instagram | E7: Engage / community | H7: Idea
A8: =DATE(Settings!$C$9,1,1)+MOD(7-WEEKDAY(DATE(Settings!$C$9,1,1),3),7)+14 | B8: =TEXT(A8,"dddd") | C8: =TEXT(A8,"mmmm") | D8: Instagram | E8: Educate | H8: Idea
A9: =DATE(Settings!$C$9,1,1)+MOD(7-WEEKDAY(DATE(Settings!$C$9,1,1),3),7)+16 | B9: =TEXT(A9,"dddd") | C9: =TEXT(A9,"mmmm") | D9: Facebook | E9: Behind the scenes | H9: Idea
A10: =DATE(Settings!$C$9,1,1)+MOD(7-WEEKDAY(DATE(Settings!$C$9,1,1),3),7)+18 | B10: =TEXT(A10,"dddd") | C10: =TEXT(A10,"mmmm") | D10: Instagram | E10: Social proof | H10: Idea
A11: =DATE(Settings!$C$9,1,1)+MOD(7-WEEKDAY(DATE(Settings!$C$9,1,1),3),7)+21 | B11: =TEXT(A11,"dddd") | C11: =TEXT(A11,"mmmm") | D11: Instagram | E11: Offer / promo | H11: Idea
A12: =DATE(Settings!$C$9,1,1)+MOD(7-WEEKDAY(DATE(Settings!$C$9,1,1),3),7)+23 | B12: =TEXT(A12,"dddd") | C12: =TEXT(A12,"mmmm") | D12: Facebook | E12: Personal story | H12: Idea
A13: =DATE(Settings!$C$9,1,1)+MOD(7-WEEKDAY(DATE(Settings!$C$9,1,1),3),7)+25 | B13: =TEXT(A13,"dddd") | C13: =TEXT(A13,"mmmm") | D13: Instagram | E13: Engage / community | H13: Idea
A14: =DATE(Settings!$C$9,1,1)+MOD(7-WEEKDAY(DATE(Settings!$C$9,1,1),3),7)+28 | B14: =TEXT(A14,"dddd") | C14: =TEXT(A14,"mmmm") | D14: Instagram | E14: Educate | H14: Idea
A15: =DATE(Settings!$C$9,1,1)+MOD(7-WEEKDAY(DATE(Settings!$C$9,1,1),3),7)+30 | B15: =TEXT(A15,"dddd") | C15: =TEXT(A15,"mmmm") | D15: Facebook | E15: Behind the scenes | H15: Idea
A16: =DATE(Settings!$C$9,1,1)+MOD(7-WEEKDAY(DATE(Settings!$C$9,1,1),3),7)+32 | B16: =TEXT(A16,"dddd") | C16: =TEXT(A16,"mmmm") | D16: Instagram | E16: Social proof | H16: Idea
A17: =DATE(Settings!$C$9,1,1)+MOD(7-WEEKDAY(DATE(Settings!$C$9,1,1),3),7)+35 | B17: =TEXT(A17,"dddd") | C17: =TEXT(A17,"mmmm") | D17: Instagram | E17: Offer / promo | H17: Idea
A18: =DATE(Settings!$C$9,1,1)+MOD(7-WEEKDAY(DATE(Settings!$C$9,1,1),3),7)+37 | B18: =TEXT(A18,"dddd") | C18: =TEXT(A18,"mmmm") | D18: Facebook | E18: Personal story | H18: Idea
A19: =DATE(Settings!$C$9,1,1)+MOD(7-WEEKDAY(DATE(Settings!$C$9,1,1),3),7)+39 | B19: =TEXT(A19,"dddd") | C19: =TEXT(A19,"mmmm") | D19: Instagram | E19: Engage / community | H19: Idea
A20: =DATE(Settings!$C$9,1,1)+MOD(7-WEEKDAY(DATE(Settings!$C$9,1,1),3),7)+42 | B20: =TEXT(A20,"dddd") | C20: =TEXT(A20,"mmmm") | D20: Instagram | E20: Educate | H20: Idea
A21: =DATE(Settings!$C$9,1,1)+MOD(7-WEEKDAY(DATE(Settings!$C$9,1,1),3),7)+44 | B21: =TEXT(A21,"dddd") | C21: =TEXT(A21,"mmmm") | D21: Facebook | E21: Behind the scenes | H21: Idea
A22: =DATE(Settings!$C$9,1,1)+MOD(7-WEEKDAY(DATE(Settings!$C$9,1,1),3),7)+46 | B22: =TEXT(A22,"dddd") | C22: =TEXT(A22,"mmmm") | D22: Instagram | E22: Social proof | H22: Idea
A23: =DATE(Settings!$C$9,1,1)+MOD(7-WEEKDAY(DATE(Settings!$C$9,1,1),3),7)+49 | B23: =TEXT(A23,"dddd") | C23: =TEXT(A23,"mmmm") | D23: Instagram | E23: Offer / promo | H23: Idea
A24: =DATE(Settings!$C$9,1,1)+MOD(7-WEEKDAY(DATE(Settings!$C$9,1,1),3),7)+51 | B24: =TEXT(A24,"dddd") | C24: =TEXT(A24,"mmmm") | D24: Facebook | E24: Personal story | H24: Idea
A25: =DATE(Settings!$C$9,1,1)+MOD(7-WEEKDAY(DATE(Settings!$C$9,1,1),3),7)+53 | B25: =TEXT(A25,"dddd") | C25: =TEXT(A25,"mmmm") | D25: Instagram | E25: Engage / community | H25: Idea
A26: =DATE(Settings!$C$9,1,1)+MOD(7-WEEKDAY(DATE(Settings!$C$9,1,1),3),7)+56 | B26: =TEXT(A26,"dddd") | C26: =TEXT(A26,"mmmm") | D26: Instagram | E26: Educate | H26: Idea
A27: =DATE(Settings!$C$9,1,1)+MOD(7-WEEKDAY(DATE(Settings!$C$9,1,1),3),7)+58 | B27: =TEXT(A27,"dddd") | C27: =TEXT(A27,"mmmm") | D27: Facebook | E27: Behind the scenes | H27: Idea
A28: =DATE(Settings!$C$9,1,1)+MOD(7-WEEKDAY(DATE(Settings!$C$9,1,1),3),7)+60 | B28: =TEXT(A28,"dddd") | C28: =TEXT(A28,"mmmm") | D28: Instagram | E28: Social proof | H28: Idea
A29: =DATE(Settings!$C$9,1,1)+MOD(7-WEEKDAY(DATE(Settings!$C$9,1,1),3),7)+63 | B29: =TEXT(A29,"dddd") | C29: =TEXT(A29,"mmmm") | D29: Instagram | E29: Offer / promo | H29: Idea
A30: =DATE(Settings!$C$9,1,1)+MOD(7-WEEKDAY(DATE(Settings!$C$9,1,1),3),7)+65 | B30: =TEXT(A30,"dddd") | C30: =TEXT(A30,"mmmm") | D30: Facebook | E30: Personal story | H30: Idea
A31: =DATE(Settings!$C$9,1,1)+MOD(7-WEEKDAY(DATE(Settings!$C$9,1,1),3),7)+67 | B31: =TEXT(A31,"dddd") | C31: =TEXT(A31,"mmmm") | D31: Instagram | E31: Engage / community | H31: Idea
A32: =DATE(Settings!$C$9,1,1)+MOD(7-WEEKDAY(DATE(Settings!$C$9,1,1),3),7)+70 | B32: =TEXT(A32,"dddd") | C32: =TEXT(A32,"mmmm") | D32: Instagram | E32: Educate | H32: Idea
A33: =DATE(Settings!$C$9,1,1)+MOD(7-WEEKDAY(DATE(Settings!$C$9,1,1),3),7)+72 | B33: =TEXT(A33,"dddd") | C33: =TEXT(A33,"mmmm") | D33: Facebook | E33: Behind the scenes | H33: Idea
A34: =DATE(Settings!$C$9,1,1)+MOD(7-WEEKDAY(DATE(Settings!$C$9,1,1),3),7)+74 | B34: =TEXT(A34,"dddd") | C34: =TEXT(A34,"mmmm") | D34: Instagram | E34: Social proof | H34: Idea
A35: =DATE(Settings!$C$9,1,1)+MOD(7-WEEKDAY(DATE(Settings!$C$9,1,1),3),7)+77 | B35: =TEXT(A35,"dddd") | C35: =TEXT(A35,"mmmm") | D35: Instagram | E35: Offer / promo | H35: Idea
A36: =DATE(Settings!$C$9,1,1)+MOD(7-WEEKDAY(DATE(Settings!$C$9,1,1),3),7)+79 | B36: =TEXT(A36,"dddd") | C36: =TEXT(A36,"mmmm") | D36: Facebook | E36: Personal story | H36: Idea
A37: =DATE(Settings!$C$9,1,1)+MOD(7-WEEKDAY(DATE(Settings!$C$9,1,1),3),7)+81 | B37: =TEXT(A37,"dddd") | C37: =TEXT(A37,"mmmm") | D37: Instagram | E37: Engage / community | H37: Idea
A38: =DATE(Settings!$C$9,1,1)+MOD(7-WEEKDAY(DATE(Settings!$C$9,1,1),3),7)+84 | B38: =TEXT(A38,"dddd") | C38: =TEXT(A38,"mmmm") | D38: Instagram | E38: Educate | H38: Idea
A39: =DATE(Settings!$C$9,1,1)+MOD(7-WEEKDAY(DATE(Settings!$C$9,1,1),3),7)+86 | B39: =TEXT(A39,"dddd") | C39: =TEXT(A39,"mmmm") | D39: Facebook | E39: Behind the scenes | H39: Idea
A40: =DATE(Settings!$C$9,1,1)+MOD(7-WEEKDAY(DATE(Settings!$C$9,1,1),3),7)+88 | B40: =TEXT(A40,"dddd") | C40: =TEXT(A40,"mmmm") | D40: Instagram | E40: Social proof | H40: Idea
...

Sheet Weekly Planner
B2: Weekly Planner
B3: Week of:
B5: Top 3 priorities
B6: 1.
B7: 2.
B8: 3.
B10: Time block | C10: Monday | D10: Tuesday | E10: Wednesday | F10: Thursday | G10: Friday | H10: Saturday | I10: Sunday
B11: Deep work (9-11)
B12: Admin / email (11-12)
B13: Content (1-3)
B14: Sales / outreach (3-4)
B15: Learning (4-5)
B17: Habit tracker (type x) | C17: Mon | D17: Tue | E17: Wed | F17: Thu | G17: Fri | H17: Sat | I17: Sun | J17: Total
B18: Posted content | J18: =COUNTIF(C18:I18,"x")
B19: Replied to messages | J19: =COUNTIF(C19:I19,"x")
B20: Tracked money | J20: =COUNTIF(C20:I20,"x")
B21: Moved / walked | J21: =COUNTIF(C21:I21,"x")
B22: Learned something | J22: =COUNTIF(C22:I22,"x")
B24: Wins this week

Sheet Budget Tracker
A1: Monthly Budget Tracker
A3: Category | B3: Jan | C3: Feb | D3: Mar | E3: Apr | F3: May | G3: Jun | H3: Jul | I3: Aug | J3: Sep | K3: Oct | L3: Nov | M3: Dec | N3: Total
A4: INCOME
A5: Product sales | N5: =SUM(B5:M5)
A6: Services / clients | N6: =SUM(B6:M6)
A7: Affiliate / other | N7: =SUM(B7:M7)
A8: Total income | B8: =SUM(B5:B7) | C8: =SUM(C5:C7) | D8: =SUM(D5:D7) | E8: =SUM(E5:E7) | F8: =SUM(F5:F7) | G8: =SUM(G5:G7) | H8: =SUM(H5:H7) | I8: =SUM(I5:I7) | ... N8: =SUM(N5:N7)
A10: EXPENSES
A11: Software & tools | N11: =SUM(B11:M11)
A12: Advertising | N12: =SUM(B12:M12)
A13: Fees (platform, payment) | N13: =SUM(B13:M13)
A14: Contractors | N14: =SUM(B14:M14)
A15: Equipment | N15: =SUM(B15:M15)
A16: Education | N16: =SUM(B16:M16)
A17: Other | N17: =SUM(B17:M17)
A18: Total expenses | B18: =SUM(B11:B17) | C18: =SUM(C11:C17) | D18: =SUM(D11:D17) | E18: =SUM(E11:E17) | F18: =SUM(F11:F17) | G18: =SUM(G11:G17) | H18: =SUM(H11:H17) | I18: =SUM(I11:I17) | ... N18: =SUM(N11:N17)
A20: PROFIT | B20: =B8-B18 | C20: =C8-C18 | D20: =D8-D18 | E20: =E8-E18 | F20: =F8-F18 | G20: =G8-G18 | H20: =H8-H18 | I20: =I8-I18 | ... N20: =N8-N18
A21: Profit margin | B21: =IF(B8=0,"",B20/B8) | C21: =IF(C8=0,"",C20/C8) | D21: =IF(D8=0,"",D20/D8) | E21: =IF(E8=0,"",E20/E8) | F21: =IF(F8=0,"",F20/F8) | G21: =IF(G8=0,"",G20/G8) | H21: =IF(H8=0,"",H20/H8) | I21: =IF(I8=0,"",I20/I8) | ... N21: =IF(N8=0,"",N20/N8)

Sheet Post Tracker
A1: Date | B1: Platform | C1: Pillar | D1: Topic | E1: Reach | F1: Likes | G1: Comments | H1: Shares | I1: Clicks | J1: Sales | K1: Engagement rate | M1: Pillar | N1: Posts | O1: Avg engagement | P1: Sales
K2: =IF(E2=0,"",(F2+G2+H2)/E2) | M2: Educate | N2: =COUNTIF($C$2:$C$201,M2) | O2: =IFERROR(AVERAGEIF($C$2:$C$201,M2,$K$2:$K$201),"") | P2: =SUMIF($C$2:$C$201,M2,$J$2:$J$201)
K3: =IF(E3=0,"",(F3+G3+H3)/E3) | M3: Behind the scenes | N3: =COUNTIF($C$2:$C$201,M3) | O3: =IFERROR(AVERAGEIF($C$2:$C$201,M3,$K$2:$K$201),"") | P3: =SUMIF($C$2:$C$201,M3,$J$2:$J$201)
K4: =IF(E4=0,"",(F4+G4+H4)/E4) | M4: Social proof | N4: =COUNTIF($C$2:$C$201,M4) | O4: =IFERROR(AVERAGEIF($C$2:$C$201,M4,$K$2:$K$201),"") | P4: =SUMIF($C$2:$C$201,M4,$J$2:$J$201)
K5: =IF(E5=0,"",(F5+G5+H5)/E5) | M5: Offer / promo | N5: =COUNTIF($C$2:$C$201,M5) | O5: =IFERROR(AVERAGEIF($C$2:$C$201,M5,$K$2:$K$201),"") | P5: =SUMIF($C$2:$C$201,M5,$J$2:$J$201)
K6: =IF(E6=0,"",(F6+G6+H6)/E6) | M6: Personal story | N6: =COUNTIF($C$2:$C$201,M6) | O6: =IFERROR(AVERAGEIF($C$2:$C$201,M6,$K$2:$K$201),"") | P6: =SUMIF($C$2:$C$201,M6,$J$2:$J$201)
K7: =IF(E7=0,"",(F7+G7+H7)/E7) | M7: Engage / community | N7: =COUNTIF($C$2:$C$201,M7) | O7: =IFERROR(AVERAGEIF($C$2:$C$201,M7,$K$2:$K$201),"") | P7: =SUMIF($C$2:$C$201,M7,$J$2:$J$201)
K8: =IF(E8=0,"",(F8+G8+H8)/E8)
K9: =IF(E9=0,"",(F9+G9+H9)/E9) | M9: Best pillar | N9: =IFERROR(INDEX(M2:M7,MATCH(MAX(O2:O7),O2:O7,0)),"")
K10: =IF(E10=0,"",(F10+G10+H10)/E10)
K11: =IF(E11=0,"",(F11+G11+H11)/E11)
K12: =IF(E12=0,"",(F12+G12+H12)/E12)
K13: =IF(E13=0,"",(F13+G13+H13)/E13)
K14: =IF(E14=0,"",(F14+G14+H14)/E14)
K15: =IF(E15=0,"",(F15+G15+H15)/E15)
K16: =IF(E16=0,"",(F16+G16+H16)/E16)
K17: =IF(E17=0,"",(F17+G17+H17)/E17)
K18: =IF(E18=0,"",(F18+G18+H18)/E18)
K19: =IF(E19=0,"",(F19+G19+H19)/E19)
K20: =IF(E20=0,"",(F20+G20+H20)/E20)
K21: =IF(E21=0,"",(F21+G21+H21)/E21)
... K201: =IF(E201=0,"",(F201+G201+H201)/E201)
